<?xml version="1.0" encoding="utf-8"?>
<!-- This URDF was automatically created by SolidWorks to URDF Exporter! Originally created by Stephen Brawner (brawner@gmail.com) 
		 Commit Version: 1.5.1-0-g916b5db  Build Version: 1.5.7152.31018
		 For more information, please see http://wiki.ros.org/sw_urdf_exporter -->
<robot name="TY2_SW">

	<material name="red">
		<color rgba="1 0 0 1"/>
	</material>
	<material name="yallow">
		<color rgba="1 1 0 1"/>
	</material>
	<material name="white">
		<color rgba="1 1 1 1"/>
	</material>

	<link name="base_link">
	</link>
	<link name="body_link">
		<visual>
			<geometry>
				<box size="0.7 0.4 0.3" />
			</geometry>
			<origin xyz="0 0 0.08" rpy="0 0 0" />
			<material name="red" />
		</visual>
	</link>
	<link name="Lwheel_link">
		<visual>
			<geometry>
				<cylinder length="0.04" radius="0.11" />
			</geometry>
			<material name="red" />
		</visual>
	</link>
	<link name="Rwheel_link">
		<visual>
			<geometry>
				<cylinder length="0.04" radius="0.11" />
			</geometry>
			<material name="red" />
		</visual>
	</link>
	<link name="scanF_link">
		<visual>
			<geometry>
				<box size="0.14 0.14 0.08" />
			</geometry>
			<origin xyz="0 0 0.03" rpy="0 0 0" />
			<material name="yallow" />
		</visual>
	</link>
	<link name="scanB_link">
		<visual>
			<geometry>
				<box size="0.14 0.14 0.08" />
			</geometry>
			<origin xyz="0 0 0.03" rpy="0 0 0" />
			<material name="yallow" />
		</visual>
	</link>
	<link name="realsensor_link">
		<visual>
			<geometry>
				<box size="0.05 0.16 0.05" />
			</geometry>
			<material name="white" />
		</visual>
	</link>

	<joint name="base_to_Lwheel_joint" type="fixed">
		<origin xyz="0 0 0.11" rpy="0 0 0" />
		<parent link="base_link" />
		<child link="body_link" />
	</joint>

	<joint name="body_to_Lwheel_joint" type="continuous">
		<origin xyz="0 0.2738 0" rpy="-1.5707 0 0" />
		<parent link="body_link" />
		<child link="Lwheel_link" />
		<axis xyz="0 1 0" />
	</joint>
	<joint name="body_to_Rwheel_joint" type="continuous">
		<origin xyz="0 -0.2738 0" rpy="1.5707 0 0" />
		<parent link="body_link" />
		<child link="Rwheel_link" />
		<axis xyz="0 1 0" />
	</joint>
	<joint name="body_to_scanF_joint" type="fixed">>
		<origin xyz="0.33142 0.22887 0.23138" rpy="0 0 0" />
		<parent link="body_link" />
		<child link="scanF_link" />
	</joint>
	<joint name="body_to_scanB_joint" type="fixed">>
		<origin xyz="-0.33142 -0.22887 0.23138" rpy="0 0 3.1415926" />
		<parent link="body_link" />
		<child link="scanB_link" />
	</joint>
	<joint name="body_to_realsensor_joint" type="fixed">>
		<origin xyz="0.4129 0 0.2675" rpy="0 0 0" />
		<parent link="body_link" />
		<child link="realsensor_link" />
	</joint>
</robot>