<robot name="robot3_simulation" xmlns:xacro="http://ros.org/wiki/xacro">
    <material name="black">
        <color rgba="0 0 0 1"/>
    </material>
    <xacro:macro name="wheel" params="child org_xyz">
        <joint name="base_to_${child}" type="continuous">
            <origin xyz="${org_xyz}" rpy="0 ${radians(-90)} 0"/>
            <parent link="body_link"/>
            <child link="${child}"/>
            <axis xyz="0 0 1" />
            <limit velocity="12.0" effort="5" />
            <dynamics damping="0.1"/> 
        </joint>
        <transmission name="base_to_${child}_trans">
            <type>transmission_interface/SimpleTransmission</type>
            <joint name="base_to_${child}">
                <hardwareInterface>hardware_interface/VelocityJointInterface</hardwareInterface>
            </joint>
            <actuator name="base_to_${child}_motor">
                <hardwareInterface>hardware_interface/VelocityJointInterface</hardwareInterface>
                <mechanismReduction>1</mechanismReduction>
            </actuator>
        </transmission>
        <link name="${child}">
            <visual>
                <geometry>
                    <cylinder length="0.05" radius="0.05"/>
                </geometry>
                <origin rpy="0 0 0" xyz="0 0 0"/>
                <material name="black"/>
            </visual>
            <inertial>
                <origin xyz="0 0 0" rpy="0 0 0"/>
                <mass value="0.1"/>
                <inertia ixx="0.0001" ixy="0" ixz="0" iyy="0.0001" iyz="0" izz="0.0001"/>
            </inertial>
            <collision>
                <origin xyz="0 0 0" rpy="0 0 0"/>
                <geometry>
                    <cylinder length="0.048" radius="0.05"/>
                </geometry>
            </collision>
        </link>
        <gazebo reference="${child}">
            <material>Gazebo/black</material>
            <mu1 value="1.0" />
            <mu2 value="1.0" />
            <kp value="50000" />
            <kd value="10" />
        </gazebo>
    </xacro:macro>
</robot>