<robot name="robot2_simulation" xmlns:xacro="http://ros.org/wiki/xacro">
    <xacro:include filename="$(find vis_lecture)/urdf/model_laser_2D.xacro" />

    <material name="black">
        <color rgba="0 0 0 1"/>
    </material>
    <xacro:macro name="wheel" params="child org_xyz">
        <joint name="base_to_${child}" type="continuous">
            <origin xyz="${org_xyz}" rpy="0 ${radians(-90)} 0"/>
            <parent link="body_link"/>
            <child link="${child}"/>
            <axis xyz="0 0 1" />
            <!-- <limit lower="-1" upper="1" effort="1000" velocity="0.5"/> -->
        </joint>
        <link name="${child}">
            <visual>
                <geometry>
                    <cylinder length="0.05" radius="0.05"/>
                </geometry>
                <origin rpy="0 0 0" xyz="0 0 0"/>
                <material name="black"/>
            </visual>
            <inertial>
                <origin xyz="0 0 0" rpy="0 0 0"/>
                <mass value="0.1"/>
                <inertia ixx="1" ixy="0" ixz="0" iyy="1" iyz="0" izz="1"/>
            </inertial>
            <collision>
                <origin xyz="0 0 0" rpy="0 0 0"/>
                <geometry>
                    <cylinder length="0.048" radius="0.05"/>
                </geometry>
            </collision>
        </link>
        <gazebo reference="${child}">
            <material>Gazebo/black</material>
        </gazebo>
    </xacro:macro>

    <link name="base_link"/>
    <joint name="body1_joint" type="fixed">
        <parent link="base_link"/>
        <child  link="body_link"/>
        <origin rpy="0 0 0" xyz="0 0 0.075"/>
    </joint>
    <link name="body_link">
        <visual>
            <geometry>
                <box size="0.2 0.3 0.1"/>
            </geometry>
            <origin rpy="0 0 0" xyz="0 0 0"/>
            <material name="white">
                <color rgba="1 1 1 1"/>
            </material>
        </visual>
        <inertial>
            <origin xyz="0 0 0" rpy="0 0 0"/>
            <mass value="0.1"/>
            <inertia ixx="1" ixy="0" ixz="0" iyy="1" iyz="0" izz="1"/>
        </inertial>
        <collision>
            <origin xyz="0 0 0" rpy="0 0 0"/>
            <geometry>
                <cylinder length="0.05" radius="0.05"/>
            </geometry>
        </collision>
    </link>
    <gazebo reference="body_link">
        <material>Gazebo/white</material>
    </gazebo>

    <joint name="body_to_ball_joint" type="fixed">
        <origin xyz="0 0.125 -0.05" rpy="0 0 0"/>
        <parent link="body_link"/>
        <child link="ball_link"/>
    </joint>
    <link name="ball_link">
        <visual>
            <origin xyz="0 0 0" rpy="0 0 0"/>
            <geometry>
                <sphere radius="0.025"/>
            </geometry>
            <material name="white">
                <color rgba="1 1 1 1"/>
            </material>
        </visual>
        <inertial>
            <origin xyz="0 0 0" rpy="0 0 0"/>
            <mass value="0.1"/>
            <inertia ixx="1" ixy="0" ixz="0" iyy="1" iyz="0" izz="1"/>
        </inertial>
        <collision>
            <origin xyz="0 0 0" rpy="0 0 0"/>
            <geometry>
                <sphere radius="0.025"/>
            </geometry>
        </collision>
    </link>
    <gazebo reference="ball_name">
        <material>Gazebo/white</material>
    </gazebo>

    <xacro:wheel child="wheel_R" org_xyz="0.125 -0.1 -0.025" />
    <xacro:wheel child="wheel_L" org_xyz="-0.125 -0.1 -0.025" />
    <xacro:model_laser_2D parent="body_link" prefix="laser" xyz="0 0.13 0.07"  />

</robot>